<?xml version="1.0" ?>
<!-- =================================================================================== -->
<!-- |    This document was autogenerated by xacro from gvr_bot.urdf.xacro             | -->
<!-- |    EDITING THIS FILE BY HAND IS NOT RECOMMENDED                                 | -->
<!-- =================================================================================== -->
<robot name="gvr_bot" xmlns:controller="http://playerstage.sourceforge.net/gazebo/xmlschema/#controller" xmlns:interface="http://playerstage.sourceforge.net/gazebo/xmlschema/#interface" xmlns:sensor="http://playerstage.sourceforge.net/gazebo/xmlschema/#sensor" xmlns:xacro="http://playerstage.sourceforge.net/gazebo/xmlschema/#xacro">
  <link name="base_link">
    <inertial>
      <mass value="16.92"/>
      <origin rpy="0 0 0" xyz="0.0 -0.1 0.0"/>
      <inertia ixx="0.68808" ixy="0.0" ixz="0.0" iyy="0.273117" iyz="0.0" izz="0.889005"/>
    </inertial>
    <visual>
      <origin rpy="0 0 0" xyz="0.0 0.0 0.0"/>
      <geometry>
        <mesh filename="package://gvrbot_simulation/models/meshes/base_linkV4.dae"/>
      </geometry>
    </visual>
    <collision>
      <origin rpy="0 0 0" xyz="0.0 0.0 -0.0085"/>
      <geometry>
        <!--  <mesh filename="package://gvrbot_simulation/models/meshes/base_linkV4.dae"/> -->
        <box size="0.41 0.6 0.085"/>
      </geometry>
    </collision>
  </link>
  <!-- base_mark is 2cm cube marking the origin of the model and baselink, for use as a reference point -->
  <joint name="bl_to_bm" type="fixed">
    <origin rpy="0.0 0.0 0.0" xyz="0.0 0.0 0.0"/>
    <parent link="base_link"/>
    <child link="base_mark"/>
  </joint>
  <link name="base_mark">
    <inertial>
      <mass value="0.001"/>
      <origin rpy="0 0 0" xyz="0.0 0.0 0.0"/>
      <inertia ixx="0.004512" ixy="0.001692" ixz="0.001692" iyy="0.004512" iyz="0.001692" izz="0.004512"/>
    </inertial>
    <visual>
      <origin rpy="0 0 0" xyz="0.0 0.0 0.0"/>
      <geometry>
        <box size="0.02 0.02 0.02"/>
      </geometry>
    </visual>
    <collision>
      <origin rpy="0 0 0.0" xyz="0.0 0.0 0.0"/>
      <geometry>
        <box size="0.02 0.02 0.02"/>
      </geometry>
    </collision>
  </link>
  <joint name="left_0_wheel_joint" type="continuous">
    <origin rpy="0 0 0" xyz="0.165 0.251 0"/>
    <parent link="base_link"/>
    <child link="left_0_wheel_link"/>
    <axis xyz="1 0 0"/>
    <limit effort="100" velocity="100"/>
    <joint_properties damping="0.0" friction="0.0"/>
    <anchor xyz="0 0 0"/>
  </joint>
  <link name="left_0_wheel_link">
    <inertial>
      <mass value="0.1"/>
      <origin rpy="-1.570795 0 -1.570795" xyz="0 0 0"/>
      <inertia ixx="0.000221458333333" ixy="0.0" ixz="0.0" iyy="0.000221458333333" iyz="0.0" izz="0.00036125"/>
    </inertial>
    <collision>
      <origin rpy="-1.570795 0 -1.570795" xyz="0 0 0"/>
      <!-- Rotate the cyclinder to use as a wheel -->
      <geometry>
        <cylinder length="0.07" radius="0.085"/>
      </geometry>
    </collision>
    <!--
        <visual>
          <origin xyz="0 0 0" rpy="${-M_PI/2} 0 ${-M_PI/2}" /> 
          <geometry>
            <cylinder radius="${radius}" length="${height}" />
          </geometry>
        </visual>  -->
  </link>
  <gazebo reference="left_0_wheel_link">
    <mu1>10.0</mu1>
    <mu2>10.0</mu2>
    <kp>1000000.0</kp>
    <kd>100.0</kd>
    <minDepth>0.001</minDepth>
    <maxVel>1.0</maxVel>
  </gazebo>
  <transmission name="left_0_wheel_trans">
    <type>transmission_interface/SimpleTransmission</type>
    <joint name="left_0_wheel_joint">
      <hardwareInterface>EffortJointInterface</hardwareInterface>
    </joint>
    <actuator name="left_0_motor_link">
      <mechanicalReduction>1</mechanicalReduction>
      <motorTorqueConstant>1</motorTorqueConstant>
    </actuator>
  </transmission>
  <joint name="left_1_wheel_joint" type="continuous">
    <origin rpy="0 0 0" xyz="0.165 0.0 -0.001"/>
    <parent link="base_link"/>
    <child link="left_1_wheel_link"/>
    <axis xyz="1 0 0"/>
    <limit effort="100" velocity="100"/>
    <joint_properties damping="0.0" friction="0.0"/>
    <anchor xyz="0 0 0"/>
  </joint>
  <link name="left_1_wheel_link">
    <inertial>
      <mass value="0.1"/>
      <origin rpy="-1.570795 0 -1.570795" xyz="0 0 0"/>
      <inertia ixx="0.000221458333333" ixy="0.0" ixz="0.0" iyy="0.000221458333333" iyz="0.0" izz="0.00036125"/>
    </inertial>
    <collision>
      <origin rpy="-1.570795 0 -1.570795" xyz="0 0 0"/>
      <!-- Rotate the cyclinder to use as a wheel -->
      <geometry>
        <cylinder length="0.07" radius="0.085"/>
      </geometry>
    </collision>
    <!--
        <visual>
          <origin xyz="0 0 0" rpy="${-M_PI/2} 0 ${-M_PI/2}" /> 
          <geometry>
            <cylinder radius="${radius}" length="${height}" />
          </geometry>
        </visual>  -->
  </link>
  <gazebo reference="left_1_wheel_link">
    <mu1>10.0</mu1>
    <mu2>10.0</mu2>
    <kp>1000000.0</kp>
    <kd>100.0</kd>
    <minDepth>0.001</minDepth>
    <maxVel>1.0</maxVel>
  </gazebo>
  <transmission name="left_1_wheel_trans">
    <type>transmission_interface/SimpleTransmission</type>
    <joint name="left_1_wheel_joint">
      <hardwareInterface>EffortJointInterface</hardwareInterface>
    </joint>
    <actuator name="left_1_motor_link">
      <mechanicalReduction>1</mechanicalReduction>
      <motorTorqueConstant>1</motorTorqueConstant>
    </actuator>
  </transmission>
  <joint name="left_2_wheel_joint" type="continuous">
    <origin rpy="0 0 0" xyz="0.165 -0.251 0"/>
    <parent link="base_link"/>
    <child link="left_2_wheel_link"/>
    <axis xyz="1 0 0"/>
    <limit effort="100" velocity="100"/>
    <joint_properties damping="0.0" friction="0.0"/>
    <anchor xyz="0 0 0"/>
  </joint>
  <link name="left_2_wheel_link">
    <inertial>
      <mass value="0.1"/>
      <origin rpy="-1.570795 0 -1.570795" xyz="0 0 0"/>
      <inertia ixx="0.000221458333333" ixy="0.0" ixz="0.0" iyy="0.000221458333333" iyz="0.0" izz="0.00036125"/>
    </inertial>
    <collision>
      <origin rpy="-1.570795 0 -1.570795" xyz="0 0 0"/>
      <!-- Rotate the cyclinder to use as a wheel -->
      <geometry>
        <cylinder length="0.07" radius="0.085"/>
      </geometry>
    </collision>
    <!--
        <visual>
          <origin xyz="0 0 0" rpy="${-M_PI/2} 0 ${-M_PI/2}" /> 
          <geometry>
            <cylinder radius="${radius}" length="${height}" />
          </geometry>
        </visual>  -->
  </link>
  <gazebo reference="left_2_wheel_link">
    <mu1>10.0</mu1>
    <mu2>10.0</mu2>
    <kp>1000000.0</kp>
    <kd>100.0</kd>
    <minDepth>0.001</minDepth>
    <maxVel>1.0</maxVel>
  </gazebo>
  <transmission name="left_2_wheel_trans">
    <type>transmission_interface/SimpleTransmission</type>
    <joint name="left_2_wheel_joint">
      <hardwareInterface>EffortJointInterface</hardwareInterface>
    </joint>
    <actuator name="left_2_motor_link">
      <mechanicalReduction>1</mechanicalReduction>
      <motorTorqueConstant>1</motorTorqueConstant>
    </actuator>
  </transmission>
  <joint name="left_3_wheel_joint" type="continuous">
    <origin rpy="0 0 0" xyz="0.165 0.1055 0"/>
    <parent link="base_link"/>
    <child link="left_3_wheel_link"/>
    <axis xyz="1 0 0"/>
    <limit effort="100" velocity="100"/>
    <joint_properties damping="0.0" friction="0.0"/>
    <anchor xyz="0 0 0"/>
  </joint>
  <link name="left_3_wheel_link">
    <inertial>
      <mass value="0.1"/>
      <origin rpy="-1.570795 0 -1.570795" xyz="0 0 0"/>
      <inertia ixx="0.000221458333333" ixy="0.0" ixz="0.0" iyy="0.000221458333333" iyz="0.0" izz="0.00036125"/>
    </inertial>
    <collision>
      <origin rpy="-1.570795 0 -1.570795" xyz="0 0 0"/>
      <!-- Rotate the cyclinder to use as a wheel -->
      <geometry>
        <cylinder length="0.07" radius="0.085"/>
      </geometry>
    </collision>
    <!--
        <visual>
          <origin xyz="0 0 0" rpy="${-M_PI/2} 0 ${-M_PI/2}" /> 
          <geometry>
            <cylinder radius="${radius}" length="${height}" />
          </geometry>
        </visual>  -->
  </link>
  <gazebo reference="left_3_wheel_link">
    <mu1>10.0</mu1>
    <mu2>10.0</mu2>
    <kp>1000000.0</kp>
    <kd>100.0</kd>
    <minDepth>0.001</minDepth>
    <maxVel>1.0</maxVel>
  </gazebo>
  <transmission name="left_3_wheel_trans">
    <type>transmission_interface/SimpleTransmission</type>
    <joint name="left_3_wheel_joint">
      <hardwareInterface>EffortJointInterface</hardwareInterface>
    </joint>
    <actuator name="left_3_motor_link">
      <mechanicalReduction>1</mechanicalReduction>
      <motorTorqueConstant>1</motorTorqueConstant>
    </actuator>
  </transmission>
  <joint name="left_4_wheel_joint" type="continuous">
    <origin rpy="0 0 0" xyz="0.165 -0.1055 0"/>
    <parent link="base_link"/>
    <child link="left_4_wheel_link"/>
    <axis xyz="1 0 0"/>
    <limit effort="100" velocity="100"/>
    <joint_properties damping="0.0" friction="0.0"/>
    <anchor xyz="0 0 0"/>
  </joint>
  <link name="left_4_wheel_link">
    <inertial>
      <mass value="0.1"/>
      <origin rpy="-1.570795 0 -1.570795" xyz="0 0 0"/>
      <inertia ixx="0.000221458333333" ixy="0.0" ixz="0.0" iyy="0.000221458333333" iyz="0.0" izz="0.00036125"/>
    </inertial>
    <collision>
      <origin rpy="-1.570795 0 -1.570795" xyz="0 0 0"/>
      <!-- Rotate the cyclinder to use as a wheel -->
      <geometry>
        <cylinder length="0.07" radius="0.085"/>
      </geometry>
    </collision>
    <!--
        <visual>
          <origin xyz="0 0 0" rpy="${-M_PI/2} 0 ${-M_PI/2}" /> 
          <geometry>
            <cylinder radius="${radius}" length="${height}" />
          </geometry>
        </visual>  -->
  </link>
  <gazebo reference="left_4_wheel_link">
    <mu1>10.0</mu1>
    <mu2>10.0</mu2>
    <kp>1000000.0</kp>
    <kd>100.0</kd>
    <minDepth>0.001</minDepth>
    <maxVel>1.0</maxVel>
  </gazebo>
  <transmission name="left_4_wheel_trans">
    <type>transmission_interface/SimpleTransmission</type>
    <joint name="left_4_wheel_joint">
      <hardwareInterface>EffortJointInterface</hardwareInterface>
    </joint>
    <actuator name="left_4_motor_link">
      <mechanicalReduction>1</mechanicalReduction>
      <motorTorqueConstant>1</motorTorqueConstant>
    </actuator>
  </transmission>
  <joint name="left_5_wheel_joint" type="continuous">
    <origin rpy="0 0 0" xyz="0.165 0.005 0.001"/>
    <parent link="base_link"/>
    <child link="left_5_wheel_link"/>
    <axis xyz="1 0 0"/>
    <limit effort="100" velocity="100"/>
    <joint_properties damping="0.0" friction="0.0"/>
    <anchor xyz="0 0 0"/>
  </joint>
  <link name="left_5_wheel_link">
    <inertial>
      <mass value="0.1"/>
      <origin rpy="-1.570795 0 -1.570795" xyz="0 0 0"/>
      <inertia ixx="0.000221458333333" ixy="0.0" ixz="0.0" iyy="0.000221458333333" iyz="0.0" izz="0.00036125"/>
    </inertial>
    <collision>
      <origin rpy="-1.570795 0 -1.570795" xyz="0 0 0"/>
      <!-- Rotate the cyclinder to use as a wheel -->
      <geometry>
        <cylinder length="0.07" radius="0.085"/>
      </geometry>
    </collision>
    <!--
        <visual>
          <origin xyz="0 0 0" rpy="${-M_PI/2} 0 ${-M_PI/2}" /> 
          <geometry>
            <cylinder radius="${radius}" length="${height}" />
          </geometry>
        </visual>  -->
  </link>
  <gazebo reference="left_5_wheel_link">
    <mu1>10.0</mu1>
    <mu2>10.0</mu2>
    <kp>1000000.0</kp>
    <kd>100.0</kd>
    <minDepth>0.001</minDepth>
    <maxVel>1.0</maxVel>
  </gazebo>
  <transmission name="left_5_wheel_trans">
    <type>transmission_interface/SimpleTransmission</type>
    <joint name="left_5_wheel_joint">
      <hardwareInterface>EffortJointInterface</hardwareInterface>
    </joint>
    <actuator name="left_5_motor_link">
      <mechanicalReduction>1</mechanicalReduction>
      <motorTorqueConstant>1</motorTorqueConstant>
    </actuator>
  </transmission>
  <joint name="right_0_wheel_joint" type="continuous">
    <origin rpy="0 0 0" xyz="-0.165 0.251 0"/>
    <parent link="base_link"/>
    <child link="right_0_wheel_link"/>
    <axis xyz="1 0 0"/>
    <limit effort="100" velocity="100"/>
    <joint_properties damping="0.0" friction="0.0"/>
    <anchor xyz="0 0 0"/>
  </joint>
  <link name="right_0_wheel_link">
    <inertial>
      <mass value="0.1"/>
      <origin rpy="-1.570795 0 -1.570795" xyz="0 0 0"/>
      <inertia ixx="0.000221458333333" ixy="0.0" ixz="0.0" iyy="0.000221458333333" iyz="0.0" izz="0.00036125"/>
    </inertial>
    <collision>
      <origin rpy="-1.570795 0 -1.570795" xyz="0 0 0"/>
      <!-- Rotate the cyclinder to use as a wheel -->
      <geometry>
        <cylinder length="0.07" radius="0.085"/>
      </geometry>
    </collision>
    <!--
        <visual>
          <origin xyz="0 0 0" rpy="${-M_PI/2} 0 ${-M_PI/2}" /> 
          <geometry>
            <cylinder radius="${radius}" length="${height}" />
          </geometry>
        </visual>  -->
  </link>
  <gazebo reference="right_0_wheel_link">
    <mu1>10.0</mu1>
    <mu2>10.0</mu2>
    <kp>1000000.0</kp>
    <kd>100.0</kd>
    <minDepth>0.001</minDepth>
    <maxVel>1.0</maxVel>
  </gazebo>
  <transmission name="right_0_wheel_trans">
    <type>transmission_interface/SimpleTransmission</type>
    <joint name="right_0_wheel_joint">
      <hardwareInterface>EffortJointInterface</hardwareInterface>
    </joint>
    <actuator name="right_0_motor_link">
      <mechanicalReduction>1</mechanicalReduction>
      <motorTorqueConstant>1</motorTorqueConstant>
    </actuator>
  </transmission>
  <joint name="right_1_wheel_joint" type="continuous">
    <origin rpy="0 0 0" xyz="-0.165 0.0 -0.001"/>
    <parent link="base_link"/>
    <child link="right_1_wheel_link"/>
    <axis xyz="1 0 0"/>
    <limit effort="100" velocity="100"/>
    <joint_properties damping="0.0" friction="0.0"/>
    <anchor xyz="0 0 0"/>
  </joint>
  <link name="right_1_wheel_link">
    <inertial>
      <mass value="0.1"/>
      <origin rpy="-1.570795 0 -1.570795" xyz="0 0 0"/>
      <inertia ixx="0.000221458333333" ixy="0.0" ixz="0.0" iyy="0.000221458333333" iyz="0.0" izz="0.00036125"/>
    </inertial>
    <collision>
      <origin rpy="-1.570795 0 -1.570795" xyz="0 0 0"/>
      <!-- Rotate the cyclinder to use as a wheel -->
      <geometry>
        <cylinder length="0.07" radius="0.085"/>
      </geometry>
    </collision>
    <!--
        <visual>
          <origin xyz="0 0 0" rpy="${-M_PI/2} 0 ${-M_PI/2}" /> 
          <geometry>
            <cylinder radius="${radius}" length="${height}" />
          </geometry>
        </visual>  -->
  </link>
  <gazebo reference="right_1_wheel_link">
    <mu1>10.0</mu1>
    <mu2>10.0</mu2>
    <kp>1000000.0</kp>
    <kd>100.0</kd>
    <minDepth>0.001</minDepth>
    <maxVel>1.0</maxVel>
  </gazebo>
  <transmission name="right_1_wheel_trans">
    <type>transmission_interface/SimpleTransmission</type>
    <joint name="right_1_wheel_joint">
      <hardwareInterface>EffortJointInterface</hardwareInterface>
    </joint>
    <actuator name="right_1_motor_link">
      <mechanicalReduction>1</mechanicalReduction>
      <motorTorqueConstant>1</motorTorqueConstant>
    </actuator>
  </transmission>
  <joint name="right_2_wheel_joint" type="continuous">
    <origin rpy="0 0 0" xyz="-0.165 -0.251 0"/>
    <parent link="base_link"/>
    <child link="right_2_wheel_link"/>
    <axis xyz="1 0 0"/>
    <limit effort="100" velocity="100"/>
    <joint_properties damping="0.0" friction="0.0"/>
    <anchor xyz="0 0 0"/>
  </joint>
  <link name="right_2_wheel_link">
    <inertial>
      <mass value="0.1"/>
      <origin rpy="-1.570795 0 -1.570795" xyz="0 0 0"/>
      <inertia ixx="0.000221458333333" ixy="0.0" ixz="0.0" iyy="0.000221458333333" iyz="0.0" izz="0.00036125"/>
    </inertial>
    <collision>
      <origin rpy="-1.570795 0 -1.570795" xyz="0 0 0"/>
      <!-- Rotate the cyclinder to use as a wheel -->
      <geometry>
        <cylinder length="0.07" radius="0.085"/>
      </geometry>
    </collision>
    <!--
        <visual>
          <origin xyz="0 0 0" rpy="${-M_PI/2} 0 ${-M_PI/2}" /> 
          <geometry>
            <cylinder radius="${radius}" length="${height}" />
          </geometry>
        </visual>  -->
  </link>
  <gazebo reference="right_2_wheel_link">
    <mu1>10.0</mu1>
    <mu2>10.0</mu2>
    <kp>1000000.0</kp>
    <kd>100.0</kd>
    <minDepth>0.001</minDepth>
    <maxVel>1.0</maxVel>
  </gazebo>
  <transmission name="right_2_wheel_trans">
    <type>transmission_interface/SimpleTransmission</type>
    <joint name="right_2_wheel_joint">
      <hardwareInterface>EffortJointInterface</hardwareInterface>
    </joint>
    <actuator name="right_2_motor_link">
      <mechanicalReduction>1</mechanicalReduction>
      <motorTorqueConstant>1</motorTorqueConstant>
    </actuator>
  </transmission>
  <joint name="right_3_wheel_joint" type="continuous">
    <origin rpy="0 0 0" xyz="-0.165 -0.1055 0"/>
    <parent link="base_link"/>
    <child link="right_3_wheel_link"/>
    <axis xyz="1 0 0"/>
    <limit effort="100" velocity="100"/>
    <joint_properties damping="0.0" friction="0.0"/>
    <anchor xyz="0 0 0"/>
  </joint>
  <link name="right_3_wheel_link">
    <inertial>
      <mass value="0.1"/>
      <origin rpy="-1.570795 0 -1.570795" xyz="0 0 0"/>
      <inertia ixx="0.000221458333333" ixy="0.0" ixz="0.0" iyy="0.000221458333333" iyz="0.0" izz="0.00036125"/>
    </inertial>
    <collision>
      <origin rpy="-1.570795 0 -1.570795" xyz="0 0 0"/>
      <!-- Rotate the cyclinder to use as a wheel -->
      <geometry>
        <cylinder length="0.07" radius="0.085"/>
      </geometry>
    </collision>
    <!--
        <visual>
          <origin xyz="0 0 0" rpy="${-M_PI/2} 0 ${-M_PI/2}" /> 
          <geometry>
            <cylinder radius="${radius}" length="${height}" />
          </geometry>
        </visual>  -->
  </link>
  <gazebo reference="right_3_wheel_link">
    <mu1>10.0</mu1>
    <mu2>10.0</mu2>
    <kp>1000000.0</kp>
    <kd>100.0</kd>
    <minDepth>0.001</minDepth>
    <maxVel>1.0</maxVel>
  </gazebo>
  <transmission name="right_3_wheel_trans">
    <type>transmission_interface/SimpleTransmission</type>
    <joint name="right_3_wheel_joint">
      <hardwareInterface>EffortJointInterface</hardwareInterface>
    </joint>
    <actuator name="right_3_motor_link">
      <mechanicalReduction>1</mechanicalReduction>
      <motorTorqueConstant>1</motorTorqueConstant>
    </actuator>
  </transmission>
  <joint name="right_4_wheel_joint" type="continuous">
    <origin rpy="0 0 0" xyz="-0.165 0.1055 0"/>
    <parent link="base_link"/>
    <child link="right_4_wheel_link"/>
    <axis xyz="1 0 0"/>
    <limit effort="100" velocity="100"/>
    <joint_properties damping="0.0" friction="0.0"/>
    <anchor xyz="0 0 0"/>
  </joint>
  <link name="right_4_wheel_link">
    <inertial>
      <mass value="0.1"/>
      <origin rpy="-1.570795 0 -1.570795" xyz="0 0 0"/>
      <inertia ixx="0.000221458333333" ixy="0.0" ixz="0.0" iyy="0.000221458333333" iyz="0.0" izz="0.00036125"/>
    </inertial>
    <collision>
      <origin rpy="-1.570795 0 -1.570795" xyz="0 0 0"/>
      <!-- Rotate the cyclinder to use as a wheel -->
      <geometry>
        <cylinder length="0.07" radius="0.085"/>
      </geometry>
    </collision>
    <!--
        <visual>
          <origin xyz="0 0 0" rpy="${-M_PI/2} 0 ${-M_PI/2}" /> 
          <geometry>
            <cylinder radius="${radius}" length="${height}" />
          </geometry>
        </visual>  -->
  </link>
  <gazebo reference="right_4_wheel_link">
    <mu1>10.0</mu1>
    <mu2>10.0</mu2>
    <kp>1000000.0</kp>
    <kd>100.0</kd>
    <minDepth>0.001</minDepth>
    <maxVel>1.0</maxVel>
  </gazebo>
  <transmission name="right_4_wheel_trans">
    <type>transmission_interface/SimpleTransmission</type>
    <joint name="right_4_wheel_joint">
      <hardwareInterface>EffortJointInterface</hardwareInterface>
    </joint>
    <actuator name="right_4_motor_link">
      <mechanicalReduction>1</mechanicalReduction>
      <motorTorqueConstant>1</motorTorqueConstant>
    </actuator>
  </transmission>
  <joint name="right_5_wheel_joint" type="continuous">
    <origin rpy="0 0 0" xyz="-0.165 0.005 0.001"/>
    <parent link="base_link"/>
    <child link="right_5_wheel_link"/>
    <axis xyz="1 0 0"/>
    <limit effort="100" velocity="100"/>
    <joint_properties damping="0.0" friction="0.0"/>
    <anchor xyz="0 0 0"/>
  </joint>
  <link name="right_5_wheel_link">
    <inertial>
      <mass value="0.1"/>
      <origin rpy="-1.570795 0 -1.570795" xyz="0 0 0"/>
      <inertia ixx="0.000221458333333" ixy="0.0" ixz="0.0" iyy="0.000221458333333" iyz="0.0" izz="0.00036125"/>
    </inertial>
    <collision>
      <origin rpy="-1.570795 0 -1.570795" xyz="0 0 0"/>
      <!-- Rotate the cyclinder to use as a wheel -->
      <geometry>
        <cylinder length="0.07" radius="0.085"/>
      </geometry>
    </collision>
    <!--
        <visual>
          <origin xyz="0 0 0" rpy="${-M_PI/2} 0 ${-M_PI/2}" /> 
          <geometry>
            <cylinder radius="${radius}" length="${height}" />
          </geometry>
        </visual>  -->
  </link>
  <gazebo reference="right_5_wheel_link">
    <mu1>10.0</mu1>
    <mu2>10.0</mu2>
    <kp>1000000.0</kp>
    <kd>100.0</kd>
    <minDepth>0.001</minDepth>
    <maxVel>1.0</maxVel>
  </gazebo>
  <transmission name="right_5_wheel_trans">
    <type>transmission_interface/SimpleTransmission</type>
    <joint name="right_5_wheel_joint">
      <hardwareInterface>EffortJointInterface</hardwareInterface>
    </joint>
    <actuator name="right_5_motor_link">
      <mechanicalReduction>1</mechanicalReduction>
      <motorTorqueConstant>1</motorTorqueConstant>
    </actuator>
  </transmission>
  <!--  -->
  <gazebo>
    <plugin filename="libdiffdrive_plugin_multi_wheel.so" name="diffdrive_plugin_multiwheel">
      <alwaysOn>true</alwaysOn>
      <updateRate>10.0</updateRate>
      <leftJoints>left_0_wheel_joint left_1_wheel_joint left_2_wheel_joint left_3_wheel_joint left_4_wheel_joint left_5_wheel_joint</leftJoints>
      <rightJoints>right_0_wheel_joint right_1_wheel_joint right_2_wheel_joint right_3_wheel_joint right_4_wheel_joint right_5_wheel_joint</rightJoints>
      <wheelSeparation>0.68</wheelSeparation>
      <wheelDiameter>0.17</wheelDiameter>
      <torque>50000</torque>
      <interface:position name="position_iface_2"/>
      <robotNamespace>/</robotNamespace>
      <robotBaseFrame>base_link</robotBaseFrame>
      <commandTopic>/gvr_bot/cmd_vel</commandTopic>
      <publishOdometryTf>1</publishOdometryTf>
      <publishOdometryMsg>1</publishOdometryMsg>
      <odometryTopic>/gvr_bot/odom</odometryTopic>
    </plugin>
    <plugin filename="libgazebo_ros_p3d.so" name="p3d_base_controller">
      <alwaysOn>true</alwaysOn>
      <updateRate>50.0</updateRate>
      <bodyName>base_link</bodyName>
      <topicName>/gvr_bot/ground_truth/state</topicName>
      <gaussianNoise>0.01</gaussianNoise>
      <frameName>world</frameName>
      <xyzOffsets>0 0 0</xyzOffsets>
      <rpyOffsets>0 0 0</rpyOffsets>
    </plugin>
    <plugin filename="libhector_gazebo_ros_imu.so" name="imu_controller">
      <alwaysOn>true</alwaysOn>
      <updateRate>50.0</updateRate>
      <bodyName>base_link</bodyName>
      <topicName>/gvr_bot/imu_quat</topicName>
      <accelDrift>0.0 0.0 0.0</accelDrift>
      <accelGaussianNoise>0.1 0.1 0.1</accelGaussianNoise>
      <rateDrift>0.0 0.0 0.0</rateDrift>
      <rateGaussianNoise>0.05 0.05 0.05</rateGaussianNoise>
      <headingDrift>0.0</headingDrift>
      <headingGaussianNoise>0.05</headingGaussianNoise>
    </plugin>
    <!--    -->
  </gazebo>
</robot>
