<?xml version="1.0" ?>
<!-- =================================================================================== -->
<!-- |    This document was autogenerated by xacro from gvr_bot.urdf.xacro             | -->
<!-- |    EDITING THIS FILE BY HAND IS NOT RECOMMENDED                                 | -->
<!-- =================================================================================== -->
<robot name="gvr_bot" xmlns:interface="http://playerstage.sourceforge.net/gazebo/xmlschema/#interface" xmlns:xacro="http://playerstage.sourceforge.net/gazebo/xmlschema/#xacro">
  <link name="base_link">
    <inertial>
      <mass value="16.92"/>
      <origin rpy="0 0 0" xyz="0.0 -0.1 0.0"/>
      <inertia ixx="0.273117" ixy="0.0" ixz="0.0" iyy="0.68808" iyz="0.0" izz="0.889005"/>
    </inertial>
    <visual>
      <origin rpy="0 0 -1.5708" xyz="0.0 0.0 0.0"/>
      <geometry>
        <mesh filename="package://gvrbot_simulation/models/meshes/base_linkV4.dae"/>
      </geometry>
    </visual>
    <collision>
      <origin rpy="0 0 0" xyz="0.0 0.0 -0.0085"/>
      <geometry>
        <!--  <mesh filename="package://gvrbot_simulation/models/meshes/base_linkV4.dae"/> -->
        <box size="0.68 0.33 0.085"/>
      </geometry>
    </collision>
  </link>
  <!-- base_mark is 2cm cube marking the origin of the model and baselink, for use as a reference point -->
  <joint name="bl_to_bm" type="fixed">
    <origin rpy="0.0 0.0 0.0" xyz="0.0 0.0 0.0"/>
    <parent link="base_link"/>
    <child link="base_mark"/>
  </joint>
  <link name="base_mark">
    <inertial>
      <mass value="0.001"/>
      <origin rpy="0 0 0" xyz="0.0 0.0 0.0"/>
      <inertia ixx="0.004512" ixy="0.001692" ixz="0.001692" iyy="0.004512" iyz="0.001692" izz="0.004512"/>
    </inertial>
    <visual>
      <origin rpy="0 0 0" xyz="0.0 0.0 0.0"/>
      <geometry>
        <box size="0.02 0.02 0.02"/>
      </geometry>
    </visual>
    <collision>
      <origin rpy="0 0 0.0" xyz="0.0 0.0 0.0"/>
      <geometry>
        <box size="0.02 0.02 0.02"/>
      </geometry>
    </collision>
  </link>
  <joint name="left_0_wheel_joint" type="continuous">
    <origin rpy="0 0 0" xyz="0.251 0.165 0"/>
    <parent link="base_link"/>
    <child link="left_0_wheel_link"/>
    <axis xyz="0 1 0"/>
    <limit effort="100" velocity="100"/>
    <joint_properties damping="0.0" friction="0.0"/>
    <anchor xyz="0 0 0"/>
  </joint>
  <link name="left_0_wheel_link">
    <inertial>
      <mass value="0.1"/>
      <origin xyz=" 0 0 0 "/>
      <inertia ixx="0.00012411765597" ixy="0.0" ixz="0.0" iyy="0.00015218160428" iyz="0.0" izz="0.00011763977943"/>
    </inertial>
    <collision>
      <origin rpy="-1.570795 0 0" xyz="0 0 0"/>
      <geometry>
        <cylinder length="0.07" radius="0.085"/>
        <!--<box size="1.0 0.5 0.1" />-->
      </geometry>
      <!--<material name="MTWheelColMat"/>-->
    </collision>
  </link>
  <gazebo reference="left_0_wheel_link">
    <mu1>1.0</mu1>
    <mu2>1.0</mu2>
    <kp>1000000.0</kp>
    <kd>100.0</kd>
    <minDepth>0.001</minDepth>
    <maxVel>1.0</maxVel>
    <!--<fdir1>1 0 0</fdir1>-->
    <!--<maxVel>1.0</maxVel>-->
  </gazebo>
  <transmission name="left_0_wheel_trans" type="pr2_mechanism_model/SimpleTransmission">
    <actuator name="left_0_motor_link"/>
    <joint name="left_0_wheel_joint"/>
    <mechanicalReduction>1.0</mechanicalReduction>
    <motorTorqueConstant>1</motorTorqueConstant>
  </transmission>
  <joint name="left_2_wheel_joint" type="continuous">
    <origin rpy="0 0 0" xyz="0.0 0.165 -0.001"/>
    <parent link="base_link"/>
    <child link="left_2_wheel_link"/>
    <axis xyz="0 1 0"/>
    <limit effort="100" velocity="100"/>
    <joint_properties damping="0.0" friction="0.0"/>
    <anchor xyz="0 0 0"/>
  </joint>
  <link name="left_2_wheel_link">
    <inertial>
      <mass value="0.1"/>
      <origin xyz=" 0 0 0 "/>
      <inertia ixx="0.00012411765597" ixy="0.0" ixz="0.0" iyy="0.00015218160428" iyz="0.0" izz="0.00011763977943"/>
    </inertial>
    <collision>
      <origin rpy="-1.570795 0 0" xyz="0 0 0"/>
      <geometry>
        <cylinder length="0.07" radius="0.085"/>
        <!--<box size="1.0 0.5 0.1" />-->
      </geometry>
      <!--<material name="MTWheelColMat"/>-->
    </collision>
  </link>
  <gazebo reference="left_2_wheel_link">
    <mu1>1.0</mu1>
    <mu2>1.0</mu2>
    <kp>1000000.0</kp>
    <kd>100.0</kd>
    <minDepth>0.001</minDepth>
    <maxVel>1.0</maxVel>
    <!--<fdir1>1 0 0</fdir1>-->
    <!--<maxVel>1.0</maxVel>-->
  </gazebo>
  <transmission name="left_2_wheel_trans" type="pr2_mechanism_model/SimpleTransmission">
    <actuator name="left_2_motor_link"/>
    <joint name="left_2_wheel_joint"/>
    <mechanicalReduction>1.0</mechanicalReduction>
    <motorTorqueConstant>1</motorTorqueConstant>
  </transmission>
  <joint name="left_4_wheel_joint" type="continuous">
    <origin rpy="0 0 0" xyz="-0.251 0.165 0"/>
    <parent link="base_link"/>
    <child link="left_4_wheel_link"/>
    <axis xyz="0 1 0"/>
    <limit effort="100" velocity="100"/>
    <joint_properties damping="0.0" friction="0.0"/>
    <anchor xyz="0 0 0"/>
  </joint>
  <link name="left_4_wheel_link">
    <inertial>
      <mass value="0.1"/>
      <origin xyz=" 0 0 0 "/>
      <inertia ixx="0.00012411765597" ixy="0.0" ixz="0.0" iyy="0.00015218160428" iyz="0.0" izz="0.00011763977943"/>
    </inertial>
    <collision>
      <origin rpy="-1.570795 0 0" xyz="0 0 0"/>
      <geometry>
        <cylinder length="0.07" radius="0.085"/>
        <!--<box size="1.0 0.5 0.1" />-->
      </geometry>
      <!--<material name="MTWheelColMat"/>-->
    </collision>
  </link>
  <gazebo reference="left_4_wheel_link">
    <mu1>1.0</mu1>
    <mu2>1.0</mu2>
    <kp>1000000.0</kp>
    <kd>100.0</kd>
    <minDepth>0.001</minDepth>
    <maxVel>1.0</maxVel>
    <!--<fdir1>1 0 0</fdir1>-->
    <!--<maxVel>1.0</maxVel>-->
  </gazebo>
  <transmission name="left_4_wheel_trans" type="pr2_mechanism_model/SimpleTransmission">
    <actuator name="left_4_motor_link"/>
    <joint name="left_4_wheel_joint"/>
    <mechanicalReduction>1.0</mechanicalReduction>
    <motorTorqueConstant>1</motorTorqueConstant>
  </transmission>
  <joint name="right_0_wheel_joint" type="continuous">
    <origin rpy="0 0 0" xyz="0.251 -0.165 0"/>
    <parent link="base_link"/>
    <child link="right_0_wheel_link"/>
    <axis xyz="0 1 0"/>
    <limit effort="100" velocity="100"/>
    <joint_properties damping="0.0" friction="0.0"/>
    <anchor xyz="0 0 0"/>
  </joint>
  <link name="right_0_wheel_link">
    <inertial>
      <mass value="0.1"/>
      <origin xyz=" 0 0 0 "/>
      <inertia ixx="0.00012411765597" ixy="0.0" ixz="0.0" iyy="0.00015218160428" iyz="0.0" izz="0.00011763977943"/>
    </inertial>
    <collision>
      <origin rpy="-1.570795 0 0" xyz="0 0 0"/>
      <geometry>
        <cylinder length="0.07" radius="0.085"/>
        <!--<box size="1.0 0.5 0.1" />-->
      </geometry>
      <!--<material name="MTWheelColMat"/>-->
    </collision>
  </link>
  <gazebo reference="right_0_wheel_link">
    <mu1>1.0</mu1>
    <mu2>1.0</mu2>
    <kp>1000000.0</kp>
    <kd>100.0</kd>
    <minDepth>0.001</minDepth>
    <maxVel>1.0</maxVel>
    <!--<fdir1>1 0 0</fdir1>-->
    <!--<maxVel>1.0</maxVel>-->
  </gazebo>
  <transmission name="right_0_wheel_trans" type="pr2_mechanism_model/SimpleTransmission">
    <actuator name="right_0_motor_link"/>
    <joint name="right_0_wheel_joint"/>
    <mechanicalReduction>1.0</mechanicalReduction>
    <motorTorqueConstant>1</motorTorqueConstant>
  </transmission>
  <joint name="right_2_wheel_joint" type="continuous">
    <origin rpy="0 0 0" xyz="0.0 -0.165 -0.001"/>
    <parent link="base_link"/>
    <child link="right_2_wheel_link"/>
    <axis xyz="0 1 0"/>
    <limit effort="100" velocity="100"/>
    <joint_properties damping="0.0" friction="0.0"/>
    <anchor xyz="0 0 0"/>
  </joint>
  <link name="right_2_wheel_link">
    <inertial>
      <mass value="0.1"/>
      <origin xyz=" 0 0 0 "/>
      <inertia ixx="0.00012411765597" ixy="0.0" ixz="0.0" iyy="0.00015218160428" iyz="0.0" izz="0.00011763977943"/>
    </inertial>
    <collision>
      <origin rpy="-1.570795 0 0" xyz="0 0 0"/>
      <geometry>
        <cylinder length="0.07" radius="0.085"/>
        <!--<box size="1.0 0.5 0.1" />-->
      </geometry>
      <!--<material name="MTWheelColMat"/>-->
    </collision>
  </link>
  <gazebo reference="right_2_wheel_link">
    <mu1>1.0</mu1>
    <mu2>1.0</mu2>
    <kp>1000000.0</kp>
    <kd>100.0</kd>
    <minDepth>0.001</minDepth>
    <maxVel>1.0</maxVel>
    <!--<fdir1>1 0 0</fdir1>-->
    <!--<maxVel>1.0</maxVel>-->
  </gazebo>
  <transmission name="right_2_wheel_trans" type="pr2_mechanism_model/SimpleTransmission">
    <actuator name="right_2_motor_link"/>
    <joint name="right_2_wheel_joint"/>
    <mechanicalReduction>1.0</mechanicalReduction>
    <motorTorqueConstant>1</motorTorqueConstant>
  </transmission>
  <joint name="right_4_wheel_joint" type="continuous">
    <origin rpy="0 0 0" xyz="-0.251 -0.165 0"/>
    <parent link="base_link"/>
    <child link="right_4_wheel_link"/>
    <axis xyz="0 1 0"/>
    <limit effort="100" velocity="100"/>
    <joint_properties damping="0.0" friction="0.0"/>
    <anchor xyz="0 0 0"/>
  </joint>
  <link name="right_4_wheel_link">
    <inertial>
      <mass value="0.1"/>
      <origin xyz=" 0 0 0 "/>
      <inertia ixx="0.00012411765597" ixy="0.0" ixz="0.0" iyy="0.00015218160428" iyz="0.0" izz="0.00011763977943"/>
    </inertial>
    <collision>
      <origin rpy="-1.570795 0 0" xyz="0 0 0"/>
      <geometry>
        <cylinder length="0.07" radius="0.085"/>
        <!--<box size="1.0 0.5 0.1" />-->
      </geometry>
      <!--<material name="MTWheelColMat"/>-->
    </collision>
  </link>
  <gazebo reference="right_4_wheel_link">
    <mu1>1.0</mu1>
    <mu2>1.0</mu2>
    <kp>1000000.0</kp>
    <kd>100.0</kd>
    <minDepth>0.001</minDepth>
    <maxVel>1.0</maxVel>
    <!--<fdir1>1 0 0</fdir1>-->
    <!--<maxVel>1.0</maxVel>-->
  </gazebo>
  <transmission name="right_4_wheel_trans" type="pr2_mechanism_model/SimpleTransmission">
    <actuator name="right_4_motor_link"/>
    <joint name="right_4_wheel_joint"/>
    <mechanicalReduction>1.0</mechanicalReduction>
    <motorTorqueConstant>1</motorTorqueConstant>
  </transmission>
  <gazebo>
    <plugin filename="libdiffdrive_plugin_multi_wheel.so" name="diffdrive_plugin_multiwheel">
      <alwaysOn>true</alwaysOn>
      <updateRate>30.0</updateRate>
      <leftJoints>left_0_wheel_joint left_2_wheel_joint left_4_wheel_joint </leftJoints>
      <rightJoints>right_0_wheel_joint right_2_wheel_joint right_4_wheel_joint </rightJoints>
      <!-- <leftJoints>left_0_wheel_joint left_1_wheel_joint left_2_wheel_joint left_3_wheel_joint left_4_wheel_joint left_5_wheel_joint</leftJoints>
                <rightJoints>right_0_wheel_joint right_1_wheel_joint right_2_wheel_joint right_3_wheel_joint right_4_wheel_joint right_5_wheel_joint</rightJoints> -->
      <wheelSeparation>0.41</wheelSeparation>
      <wheelDiameter>0.17</wheelDiameter>
      <torque>500000</torque>
      <interface:position name="position_iface_2"/>
      <robotNamespace>/</robotNamespace>
      <robotBaseFrame>base_link</robotBaseFrame>
      <commandTopic>/gvr_bot/cmd_vel</commandTopic>
      <publishOdometryTf>1</publishOdometryTf>
      <publishOdometryMsg>1</publishOdometryMsg>
      <odometryTopic>/gvr_bot/odom</odometryTopic>
    </plugin>
    <plugin filename="libgazebo_ros_p3d.so" name="p3d_base_controller">
      <alwaysOn>true</alwaysOn>
      <updateRate>50.0</updateRate>
      <bodyName>base_link</bodyName>
      <topicName>/gvr_bot/ground_truth/state</topicName>
      <gaussianNoise>0.01</gaussianNoise>
      <frameName>world</frameName>
      <xyzOffsets>0 0 0</xyzOffsets>
      <rpyOffsets>0 0 0</rpyOffsets>
    </plugin>
    <plugin filename="libhector_gazebo_ros_imu.so" name="imu_controller">
      <alwaysOn>true</alwaysOn>
      <updateRate>50.0</updateRate>
      <bodyName>base_link</bodyName>
      <topicName>/gvr_bot/imu_quat</topicName>
      <accelDrift>0.0 0.0 0.0</accelDrift>
      <accelGaussianNoise>0.1 0.1 0.1</accelGaussianNoise>
      <rateDrift>0.0 0.0 0.0</rateDrift>
      <rateGaussianNoise>0.05 0.05 0.05</rateGaussianNoise>
      <headingDrift>0.0</headingDrift>
      <headingGaussianNoise>0.05</headingGaussianNoise>
    </plugin>
    <!--   -->
  </gazebo>
</robot>
